Workbook

Sheet Start Here
B2: Threat Modeling + Risk Management Framework
B3: Asset & Mitigation Checklist · FNIT Guy, your Friendly Neighborhood IT Guy · 2026 edition
B6: In this sheet, you’ll find a succinct reference to assist you in protecting what’s important to you. This isn’t meant to be comprehensive but to act as a launching pad and foundation for your own research. You’ll see in some of the tabs there is a column labeled “STIG” AKA Security Technical Implementation Guide. This is where you’ll find very specific hardening guidance for your specific application or device. You’ll see a link listed in the comments for those columns, use them!
B8: How to use this workbook
B10: 1 Learn the basics | D10: 2 Take inventory | F10: 3 Fix the red
B11: Skim Definitions, Reducing Attack Surface and Common Attack Vectors. | D11: Fill in Devices, Accounts, Applications and Information. Pick answers from the dropdowns. | F11: Every tracker has a Priority column. Knock out “Fix first” items, then work down.
B13: Legend: white cells are yours to fill in; gray italic rows are examples. Green = good · Yellow = check it · Red = gap to fix
B15: Your scorecard
B17: =COUNTA('Devices'!B8:B207)+COUNTA('Accounts'!B8:B207)+COUNTA('Applications'!B8:B207)+COUNTA('Information'!B8:B207) | D17: =SUM('Devices'!N8:N207)+SUM('Accounts'!J8:J207)+SUM('Applications'!I8:I207)+SUM('Information'!J8:J207) | F17: =COUNTIF('Devices'!O8:O207,"Fix first")+COUNTIF('Accounts'!K8:K207,"Fix first")+COUNTIF('Applications'!J8:J207,"Fix first")+COUNTIF('Information'!K8:K207,"Fix first")
B18: Items tracked across all four checklists | D18: Open gaps | F18: “Fix first” items (High category with gaps)
B20: =IF((COUNTA('Devices'!B8:B207)+COUNTA('Accounts'!B8:B207)+COUNTA('Applications'!B8:B207)+COUNTA('Information'!B8:B207))=0,"–",(COUNTIF('Devices'!O8:O207,"Done")+COUNTIF('Accounts'!K8:K207,"Done")+COUNTIF('Applications'!J8:J207,"Done")+COUNTIF('Information'!K8:K207,"Done"))/(COUNTA('Devices'!B8:B207)+COUNTA('Accounts'!B8:B207)+COUNTA('Applications'!B8:B207)+COUNTA('Information'!B8:B207))) | D20: =IF(COUNTA('Accounts'!B8:B207)=0,"–",COUNTIF('Accounts'!F8:F207,"Yes")/COUNTA('Accounts'!B8:B207)) | F20: =IF(COUNTA('Information'!B8:B207)=0,"–",COUNTIF('Information'!F8:F207,"Yes")/COUNTA('Information'!B8:B207))
B21: Items fully done (no gaps) | D21: Accounts with MFA or passkeys | F21: Important info with an off-device backup
B23: Updates automatically as you fill in the checklists (example rows aren’t counted).
B25: First questions
B27: What do I want to protect?
B28: Who do I want to protect it from?
B29: How likely is it that I’ll need to protect it?
B30: How bad are the consequences if I fail?
B31: How much trouble am I willing to go through to prevent those consequences?
B33: The framework
B35: 1 | C35: Asset inventory
C36: What do we need to protect?
B38: 2 | C38: Security category
C39: Accounts · Devices · Applications · Information
B41: 3 | C41: Threat inventory
C42: Threat source? Identify threats · Who/What · Attack vectors
B44: 4 | C44: Assess vulnerabilities
C45: Accounts – reduce attack surface, make it very difficult to gain unauthorized access
C46: Poor password security · Password reuse · Weak passwords · No MFA
C47: Devices – reduce attack surface, harden what’s left
C48: Poor password security · Weak passwords · No MFA · Passwords stored in clear text · Weak baseline security configurations · No hardening · Unnecessary services enabled · Unnecessary applications downloaded · Lack of network security · No longer supported
C49: Applications
C50: Weak configurations · No security · Out of date
C51: Information
C52: No backup · No encryption
B54: 5 | C54: Identify and implement controls to mitigate risk
C55: Threat + vulnerability = risk. Are there threats? Are there vulnerabilities? Is there risk? Yes. Controls to fix.
B58: What’s inside
B60: Definitions → | D60: Threats, vulnerabilities, phishing, passkeys and more, in plain English.
B61: Reducing Attack Surface → | D61: The house-and-thief analogy, plus ten practical ways to shrink your attack surface.
...

Sheet Definitions
B2: Definitions | D2: ← Start Here
B3: The words you’ll see throughout this workbook
B6: Term | C6: Definition | D6: Source
B8: THE BASICS
B9: Threat | C9: Anyone or anything that could cause harm: a thief, a scammer, malware, even a flood.
B10: Vulnerability | C10: A weakness a threat can use: an unpatched app, a reused password, an unlocked door.
B11: Risk | C11: Threat + vulnerability. If both exist, you have risk – and controls are how you reduce it.
B12: Attack surface | C12: The sum of all the points where an unauthorized user can access a system.
B13: Attack vector | C13: The means by which a threat gains access to a point of entry.
B15: SOCIAL ENGINEERING
B16: Social engineering | C16: A general term for attackers trying to trick people into revealing sensitive information or performing certain actions, such as downloading and executing files that appear to be benign but are actually malicious.
B17: Phishing | C17: Tricking individuals into disclosing sensitive personal information through deceptive computer-based means. | D17: NIST SP 800-83
C18: Deceiving individuals into disclosing sensitive personal information through deceptive computer-based means. | D18: CNSSI-4009
C19: A digital form of social engineering that uses authentic-looking—but bogus—emails to request information from users or direct them to a fake Web site that requests information. | D19: NIST SP 800-115
B20: Vishing | C20: See phishing, but with voice (phone calls).
B21: Smishing | C21: See phishing, but via SMS (text messages).
B22: Pretexting | C22: Building a fake but believable scenario (“this is IT support”, “this is your bank”) to trick someone into taking an action, frequently by phone. | D22: Verizon 2026 DBIR
B24: PROTECTING YOURSELF
B25: MFA | C25: Multi-factor authentication: a second proof on top of your password, like an authenticator app code, a security key or a passkey.
B26: Passkey | C26: A replacement for passwords that uses your phone or computer (and its fingerprint, face or PIN) to sign you in. Passkeys can’t be phished, guessed or reused. | D26: FIDO Alliance
B27: Password manager | C27: An app that creates, stores and fills a unique, strong password for every account, so you only have to remember one. | D27: CISA
B28: STIG | C28: Security Technical Implementation Guide: very specific hardening instructions for a product, published by DISA for the U.S. Department of Defense. | D28: DISA
B29: Zero-day | C29: A vulnerability attackers are using before the vendor has released a fix.
B30: Ransomware | C30: Malware that locks or steals your files and demands payment. Good, tested backups take away its power.
B31: End of life (EOL) | C31: A product the vendor no longer supports with security updates. It will never be patched again.
B33: Glossary source: | C33: NIST IR 7298 Rev. 2 – Glossary of Key Information Security Terms

Sheet Reducing Attack Surface
B2: Reducing Attack Surface | G2: ← Start Here
B3: Fewer ways in, and harder ones
B6: Attack Surface is the sum of all the points where an unauthorized user can access a system. Think of your attack surface as points of entry into your home, the threat as a thief, and the attack vector as the means by which the threat gains access to the point of entry. Our goal is to reduce the available entry points, increase the difficulty of the thief’s job, and render the thief’s attack vector useless.
B7: In this case, if we live in a neighborhood where it is likely that thieves will rob us, we may put bars on our windows. We may put extra locks or a bracing mechanism on the door. We may refuse to answer the door when someone suspicious knocks. Furthermore, we are building up our castle (HARDENING) to prevent the petty thieves from accessing our resources.
B8: Maintain the balance. We might make our house so secure that even WE can’t get into it. The opposite is also true, we may allow our house to be so accessible that anyone can waltz in. How can we maintain the balance? We threat model and end with risk mitigation!
B10: Practical attack surface reduction
B12: 1 | C12: Enable automatic updates. Exploiting unpatched software is now the #1 way breaches start.
B13: 2 | C13: Retire end-of-life devices. If the vendor no longer ships security updates, the device will never be patched.
B14: 3 | C14: Update your router. Install firmware updates and change the default admin password. Routers and other edge devices are a favorite target.
B15: 4 | C15: Disable unnecessary services.
B16: 5 | C16: Delete unused applications. Use your web browser instead of applications when possible.
B17: 6 | C17: Configure devices and applications correctly. Reference a STIG or vendor documentation.
B18: 7 | C18: Implement least privilege. Separate your accounts into one administrator and one user, and actually restrict user rights following separation of roles.
B19: 8 | C19: Use a password manager. Let it create a unique, strong password for every account.
B20: 9 | C20: Turn on MFA – or better, passkeys. Passkeys can’t be phished or reused. Use them wherever they’re offered.
B21: 10 | C21: Back up your things, frequently! This will protect you from mistakes AND ransomware. Keep one copy off the device, and test a restore now and then.
B23: These are some examples. Your device/application specific STIG will be comprehensive in helping you configure your applications and devices properly. It will likely point you in the right direction in disabling unnecessary services.
B25: What this means for you
B27: You’ll notice when looking at the next tab that unpatched vulnerabilities, weak or stolen passwords, and phishing (social engineering) are the leading attack vectors. This means that if we cover those bases we’ll be much safer!
B28: Next: Common Attack Vectors →

Sheet Common Attack Vectors
B2: Common Attack Vectors | L2: ← Start Here
B3: How attackers actually get in, and what that means for you
B6: Here you’ll find some statistics regarding common attack vectors. These statistics were gathered primarily from businesses who were victims of attacks. They are still relevant to us because regardless of the percentages, among all cyber attacks there is a common theme:
B8: 01 Vulnerability exploitation | C8: unpatched or misconfigured systems – now the #1 way in
B9: 02 Phishing attacks | C9: social engineering, increasingly by text and phone
B10: 03 Weak credentials | C10: reused, guessed or stolen passwords
B11: 04 Ransomware | C11: generally delivered via social engineering attempts
B13: How we defend
B15: • We can avoid phishing, smishing, and vishing attacks by being hyper aware of email, text, and calls that are not from somebody we explicitly know. Be extra careful on your phone – people click more there.
B16: • We can check to see if our accounts have been compromised on haveibeenpwned.com, ensure that we do not have weak or reused passwords (a password manager makes this easy), and enable multi-factor authentication or passkeys.
B17: • We can ensure that our systems are set up to automatically update, thereby applying critical security patches before an attacker can exploit them. This will not protect you from “zero-days”, but the majority of zero-days are patched quickly and automatic updates will keep the vulnerability window as small as possible.
B18: • We can ensure our devices and applications are hardened to a reasonable degree, and replace ones that no longer get security updates.
B19: • We can ensure we are frequently backing up our files to prevent the effectiveness of ransomware.
B21: NOTE: The number one agent that leads to compromise is ultimately ourselves. There are many free cyber security awareness programs online that can help educate you. A little goes a long way!
B23: The numbers: Verizon 2026 Data Breach Investigations Report
B25: 22,000+ confirmed data breaches in 145 countries, collected from October 2024 to November 2025.
B27: 0.31 | C27: 0.48 | G27: 0.62 | J27: 0.4
B28: of breaches now start by exploiting a software vulnerability – the #1 way in | C28: of breaches involve ransomware (up from 44%) | G28: involve the human element: a mistake, a click, a scam | J28: higher click rates on phone-based scams (texts, calls) than on email
B30: How breaches start known initial access vectors, % of breaches
C31: 2025 DBIR | D31: 2026 DBIR
B32: Exploiting a vulnerability | C32: 0.2 | D32: 0.31
B33: Phishing | C33: 0.16 | D33: 0.16
B34: Credential abuse (stolen/guessed passwords) | C34: 0.22 | D34: 0.13
B35: Source: Verizon DBIR 2025 and 2026. Pretexting (fake-scenario scams) added another 6% in 2026.
B43: The bigger picture % of breaches
C44: 2025 DBIR | D44: 2026 DBIR
B45: Ransomware present | C45: 0.44 | D45: 0.48
B46: Human element involved | C46: 0.6 | D46: 0.62
B47: Third party involved | C47: 0.3 | D47: 0.48
B48: Source: Verizon DBIR 2025 and 2026 executive summaries (2025 human element reported as “around 60%”).
B56: Small and medium-sized businesses (2026 DBIR)
B58: • Initial access: exploiting vulnerabilities 26%, credential abuse 13%, phishing 9%.
B59: • Every SMB breach in the dataset came from outside attackers, and all were financially motivated.
B60: • Small organizations are disproportionately hit by ransomware – the 2025 DBIR found it in 88% of SMB breaches.
B62: Read the full 2026 DBIR →

Sheet Devices
B2: Devices | O2: ← Start Here
B3: Everything you own or manage that could be a way in
B5: List every device: phones, laptops, desktops, tablets, routers, smart-home gear, NAS, consoles. Order this by security category. Pick answers from the dropdowns; hover a column header for tips.
B6: Device | C6: Security Category | D6: Infected | E6: Backup | F6: Password Protected | G6: Password Complexity | H6: Unique Password | I6: OS Encryption | J6: STIG | K6: Physical Security | L6: Automatic Updates | M6: Still Supported | N6: Gaps | O6: Priority
B7: Example: personal laptop | C7: High | D7: No | E7: Yes | F7: Yes | G7: Complex | H7: Yes | I7: Yes | J7: No | K7: Yes | L7: Yes | M7: Yes | N7: =IF(B7="","",(D7="Yes")+(E7="No")+(F7="No")+(G7="Weak")+(H7="No")+(I7="No")+(J7="No")+(K7="No")+(L7="No")+(M7="No")) | O7: =IF(B7="","",IF(N7=0,"Done",IF(C7="High","Fix first",IF(C7="Moderate","Fix next",IF(C7="Low","Later","Set category")))))
N8: =IF(B8="","",(D8="Yes")+(E8="No")+(F8="No")+(G8="Weak")+(H8="No")+(I8="No")+(J8="No")+(K8="No")+(L8="No")+(M8="No")) | O8: =IF(B8="","",IF(N8=0,"Done",IF(C8="High","Fix first",IF(C8="Moderate","Fix next",IF(C8="Low","Later","Set category")))))
N9: =IF(B9="","",(D9="Yes")+(E9="No")+(F9="No")+(G9="Weak")+(H9="No")+(I9="No")+(J9="No")+(K9="No")+(L9="No")+(M9="No")) | O9: =IF(B9="","",IF(N9=0,"Done",IF(C9="High","Fix first",IF(C9="Moderate","Fix next",IF(C9="Low","Later","Set category")))))
N10: =IF(B10="","",(D10="Yes")+(E10="No")+(F10="No")+(G10="Weak")+(H10="No")+(I10="No")+(J10="No")+(K10="No")+(L10="No")+(M10="No")) | O10: =IF(B10="","",IF(N10=0,"Done",IF(C10="High","Fix first",IF(C10="Moderate","Fix next",IF(C10="Low","Later","Set category")))))
N11: =IF(B11="","",(D11="Yes")+(E11="No")+(F11="No")+(G11="Weak")+(H11="No")+(I11="No")+(J11="No")+(K11="No")+(L11="No")+(M11="No")) | O11: =IF(B11="","",IF(N11=0,"Done",IF(C11="High","Fix first",IF(C11="Moderate","Fix next",IF(C11="Low","Later","Set category")))))
N12: =IF(B12="","",(D12="Yes")+(E12="No")+(F12="No")+(G12="Weak")+(H12="No")+(I12="No")+(J12="No")+(K12="No")+(L12="No")+(M12="No")) | O12: =IF(B12="","",IF(N12=0,"Done",IF(C12="High","Fix first",IF(C12="Moderate","Fix next",IF(C12="Low","Later","Set category")))))
N13: =IF(B13="","",(D13="Yes")+(E13="No")+(F13="No")+(G13="Weak")+(H13="No")+(I13="No")+(J13="No")+(K13="No")+(L13="No")+(M13="No")) | O13: =IF(B13="","",IF(N13=0,"Done",IF(C13="High","Fix first",IF(C13="Moderate","Fix next",IF(C13="Low","Later","Set category")))))
N14: =IF(B14="","",(D14="Yes")+(E14="No")+(F14="No")+(G14="Weak")+(H14="No")+(I14="No")+(J14="No")+(K14="No")+(L14="No")+(M14="No")) | O14: =IF(B14="","",IF(N14=0,"Done",IF(C14="High","Fix first",IF(C14="Moderate","Fix next",IF(C14="Low","Later","Set category")))))
N15: =IF(B15="","",(D15="Yes")+(E15="No")+(F15="No")+(G15="Weak")+(H15="No")+(I15="No")+(J15="No")+(K15="No")+(L15="No")+(M15="No")) | O15: =IF(B15="","",IF(N15=0,"Done",IF(C15="High","Fix first",IF(C15="Moderate","Fix next",IF(C15="Low","Later","Set category")))))
N16: =IF(B16="","",(D16="Yes")+(E16="No")+(F16="No")+(G16="Weak")+(H16="No")+(I16="No")+(J16="No")+(K16="No")+(L16="No")+(M16="No")) | O16: =IF(B16="","",IF(N16=0,"Done",IF(C16="High","Fix first",IF(C16="Moderate","Fix next",IF(C16="Low","Later","Set category")))))
N17: =IF(B17="","",(D17="Yes")+(E17="No")+(F17="No")+(G17="Weak")+(H17="No")+(I17="No")+(J17="No")+(K17="No")+(L17="No")+(M17="No")) | O17: =IF(B17="","",IF(N17=0,"Done",IF(C17="High","Fix first",IF(C17="Moderate","Fix next",IF(C17="Low","Later","Set category")))))
N18: =IF(B18="","",(D18="Yes")+(E18="No")+(F18="No")+(G18="Weak")+(H18="No")+(I18="No")+(J18="No")+(K18="No")+(L18="No")+(M18="No")) | O18: =IF(B18="","",IF(N18=0,"Done",IF(C18="High","Fix first",IF(C18="Moderate","Fix next",IF(C18="Low","Later","Set category")))))
N19: =IF(B19="","",(D19="Yes")+(E19="No")+(F19="No")+(G19="Weak")+(H19="No")+(I19="No")+(J19="No")+(K19="No")+(L19="No")+(M19="No")) | O19: =IF(B19="","",IF(N19=0,"Done",IF(C19="High","Fix first",IF(C19="Moderate","Fix next",IF(C19="Low","Later","Set category")))))
... N207: =IF(B207="","",(D207="Yes")+(E207="No")+(F207="No")+(G207="Weak")+(H207="No")+(I207="No")+(J207="No")+(K207="No")+(L207="No")+(M207="No")) | O207: =IF(B207="","",IF(N207=0,"Done",IF(C207="High","Fix first",IF(C207="Moderate","Fix next",IF(C207="Low","Later","Set category")))))

Sheet Accounts
B2: Accounts | K2: ← Start Here
B3: Every login that protects something you care about
B5: List every account: email, banking, social media, shopping, work, cloud storage, password manager. Order this by security category. Check each email address at haveibeenpwned.com.
B6: Account | C6: Security Category | D6: Unique Password | E6: Complex Password | F6: MFA | G6: Account Hardening | H6: Password Sharing | I6: Pwned? | J6: Gaps | K6: Priority
B7: Example: primary email | C7: High | D7: Yes | E7: Yes | F7: Yes | G7: No | H7: Safe | I7: Clean | J7: =IF(B7="","",(D7="No")+(E7="No")+(F7="No")+(G7="No")+(H7="Shared")+(I7="Compromised")) | K7: =IF(B7="","",IF(J7=0,"Done",IF(C7="High","Fix first",IF(C7="Moderate","Fix next",IF(C7="Low","Later","Set category")))))
J8: =IF(B8="","",(D8="No")+(E8="No")+(F8="No")+(G8="No")+(H8="Shared")+(I8="Compromised")) | K8: =IF(B8="","",IF(J8=0,"Done",IF(C8="High","Fix first",IF(C8="Moderate","Fix next",IF(C8="Low","Later","Set category")))))
J9: =IF(B9="","",(D9="No")+(E9="No")+(F9="No")+(G9="No")+(H9="Shared")+(I9="Compromised")) | K9: =IF(B9="","",IF(J9=0,"Done",IF(C9="High","Fix first",IF(C9="Moderate","Fix next",IF(C9="Low","Later","Set category")))))
J10: =IF(B10="","",(D10="No")+(E10="No")+(F10="No")+(G10="No")+(H10="Shared")+(I10="Compromised")) | K10: =IF(B10="","",IF(J10=0,"Done",IF(C10="High","Fix first",IF(C10="Moderate","Fix next",IF(C10="Low","Later","Set category")))))
J11: =IF(B11="","",(D11="No")+(E11="No")+(F11="No")+(G11="No")+(H11="Shared")+(I11="Compromised")) | K11: =IF(B11="","",IF(J11=0,"Done",IF(C11="High","Fix first",IF(C11="Moderate","Fix next",IF(C11="Low","Later","Set category")))))
J12: =IF(B12="","",(D12="No")+(E12="No")+(F12="No")+(G12="No")+(H12="Shared")+(I12="Compromised")) | K12: =IF(B12="","",IF(J12=0,"Done",IF(C12="High","Fix first",IF(C12="Moderate","Fix next",IF(C12="Low","Later","Set category")))))
J13: =IF(B13="","",(D13="No")+(E13="No")+(F13="No")+(G13="No")+(H13="Shared")+(I13="Compromised")) | K13: =IF(B13="","",IF(J13=0,"Done",IF(C13="High","Fix first",IF(C13="Moderate","Fix next",IF(C13="Low","Later","Set category")))))
J14: =IF(B14="","",(D14="No")+(E14="No")+(F14="No")+(G14="No")+(H14="Shared")+(I14="Compromised")) | K14: =IF(B14="","",IF(J14=0,"Done",IF(C14="High","Fix first",IF(C14="Moderate","Fix next",IF(C14="Low","Later","Set category")))))
J15: =IF(B15="","",(D15="No")+(E15="No")+(F15="No")+(G15="No")+(H15="Shared")+(I15="Compromised")) | K15: =IF(B15="","",IF(J15=0,"Done",IF(C15="High","Fix first",IF(C15="Moderate","Fix next",IF(C15="Low","Later","Set category")))))
J16: =IF(B16="","",(D16="No")+(E16="No")+(F16="No")+(G16="No")+(H16="Shared")+(I16="Compromised")) | K16: =IF(B16="","",IF(J16=0,"Done",IF(C16="High","Fix first",IF(C16="Moderate","Fix next",IF(C16="Low","Later","Set category")))))
J17: =IF(B17="","",(D17="No")+(E17="No")+(F17="No")+(G17="No")+(H17="Shared")+(I17="Compromised")) | K17: =IF(B17="","",IF(J17=0,"Done",IF(C17="High","Fix first",IF(C17="Moderate","Fix next",IF(C17="Low","Later","Set category")))))
J18: =IF(B18="","",(D18="No")+(E18="No")+(F18="No")+(G18="No")+(H18="Shared")+(I18="Compromised")) | K18: =IF(B18="","",IF(J18=0,"Done",IF(C18="High","Fix first",IF(C18="Moderate","Fix next",IF(C18="Low","Later","Set category")))))
J19: =IF(B19="","",(D19="No")+(E19="No")+(F19="No")+(G19="No")+(H19="Shared")+(I19="Compromised")) | K19: =IF(B19="","",IF(J19=0,"Done",IF(C19="High","Fix first",IF(C19="Moderate","Fix next",IF(C19="Low","Later","Set category")))))
... J207: =IF(B207="","",(D207="No")+(E207="No")+(F207="No")+(G207="No")+(H207="Shared")+(I207="Compromised")) | K207: =IF(B207="","",IF(J207=0,"Done",IF(C207="High","Fix first",IF(C207="Moderate","Fix next",IF(C207="Low","Later","Set category")))))

Sheet Applications
B2: Applications | J2: ← Start Here
B3: Now’s your time to shine!
B5: This one is for you to do! We started the columns for you: list the apps on your phone and computers, order them by security category, and delete anything you don’t need.
B6: Application | C6: Security Category | D6: Up to Date | E6: Official Source | F6: Permissions Reviewed | G6: Sign-in Protected | H6: Still Needed | I6: Gaps | J6: Priority
B7: Example: banking app | C7: High | D7: Yes | E7: Yes | F7: Yes | G7: Yes | H7: Yes | I7: =IF(B7="","",(D7="No")+(E7="No")+(F7="No")+(G7="No")+(H7="No")) | J7: =IF(B7="","",IF(I7=0,"Done",IF(C7="High","Fix first",IF(C7="Moderate","Fix next",IF(C7="Low","Later","Set category")))))
I8: =IF(B8="","",(D8="No")+(E8="No")+(F8="No")+(G8="No")+(H8="No")) | J8: =IF(B8="","",IF(I8=0,"Done",IF(C8="High","Fix first",IF(C8="Moderate","Fix next",IF(C8="Low","Later","Set category")))))
I9: =IF(B9="","",(D9="No")+(E9="No")+(F9="No")+(G9="No")+(H9="No")) | J9: =IF(B9="","",IF(I9=0,"Done",IF(C9="High","Fix first",IF(C9="Moderate","Fix next",IF(C9="Low","Later","Set category")))))
I10: =IF(B10="","",(D10="No")+(E10="No")+(F10="No")+(G10="No")+(H10="No")) | J10: =IF(B10="","",IF(I10=0,"Done",IF(C10="High","Fix first",IF(C10="Moderate","Fix next",IF(C10="Low","Later","Set category")))))
I11: =IF(B11="","",(D11="No")+(E11="No")+(F11="No")+(G11="No")+(H11="No")) | J11: =IF(B11="","",IF(I11=0,"Done",IF(C11="High","Fix first",IF(C11="Moderate","Fix next",IF(C11="Low","Later","Set category")))))
I12: =IF(B12="","",(D12="No")+(E12="No")+(F12="No")+(G12="No")+(H12="No")) | J12: =IF(B12="","",IF(I12=0,"Done",IF(C12="High","Fix first",IF(C12="Moderate","Fix next",IF(C12="Low","Later","Set category")))))
I13: =IF(B13="","",(D13="No")+(E13="No")+(F13="No")+(G13="No")+(H13="No")) | J13: =IF(B13="","",IF(I13=0,"Done",IF(C13="High","Fix first",IF(C13="Moderate","Fix next",IF(C13="Low","Later","Set category")))))
I14: =IF(B14="","",(D14="No")+(E14="No")+(F14="No")+(G14="No")+(H14="No")) | J14: =IF(B14="","",IF(I14=0,"Done",IF(C14="High","Fix first",IF(C14="Moderate","Fix next",IF(C14="Low","Later","Set category")))))
I15: =IF(B15="","",(D15="No")+(E15="No")+(F15="No")+(G15="No")+(H15="No")) | J15: =IF(B15="","",IF(I15=0,"Done",IF(C15="High","Fix first",IF(C15="Moderate","Fix next",IF(C15="Low","Later","Set category")))))
I16: =IF(B16="","",(D16="No")+(E16="No")+(F16="No")+(G16="No")+(H16="No")) | J16: =IF(B16="","",IF(I16=0,"Done",IF(C16="High","Fix first",IF(C16="Moderate","Fix next",IF(C16="Low","Later","Set category")))))
I17: =IF(B17="","",(D17="No")+(E17="No")+(F17="No")+(G17="No")+(H17="No")) | J17: =IF(B17="","",IF(I17=0,"Done",IF(C17="High","Fix first",IF(C17="Moderate","Fix next",IF(C17="Low","Later","Set category")))))
I18: =IF(B18="","",(D18="No")+(E18="No")+(F18="No")+(G18="No")+(H18="No")) | J18: =IF(B18="","",IF(I18=0,"Done",IF(C18="High","Fix first",IF(C18="Moderate","Fix next",IF(C18="Low","Later","Set category")))))
I19: =IF(B19="","",(D19="No")+(E19="No")+(F19="No")+(G19="No")+(H19="No")) | J19: =IF(B19="","",IF(I19=0,"Done",IF(C19="High","Fix first",IF(C19="Moderate","Fix next",IF(C19="Low","Later","Set category")))))
... I207: =IF(B207="","",(D207="No")+(E207="No")+(F207="No")+(G207="No")+(H207="No")) | J207: =IF(B207="","",IF(I207=0,"Done",IF(C207="High","Fix first",IF(C207="Moderate","Fix next",IF(C207="Low","Later","Set category")))))

Sheet Information
B2: Information | K2: ← Start Here
B3: The data you can’t afford to lose or leak
B5: List the information that matters: photos, tax and financial records, IDs and passports, medical records, work files, password manager vault. Order this by security category.
B6: Information | C6: Security Category | D6: Where It Lives | E6: Backed Up | F6: Off-device Copy | G6: Restore Tested | H6: Encrypted | I6: Access Limited | J6: Gaps | K6: Priority
B7: Example: tax & financial records | C7: High | D7: Laptop + cloud drive | E7: Yes | F7: Yes | G7: No | H7: Yes | I7: Yes | J7: =IF(B7="","",(E7="No")+(F7="No")+(G7="No")+(H7="No")+(I7="No")) | K7: =IF(B7="","",IF(J7=0,"Done",IF(C7="High","Fix first",IF(C7="Moderate","Fix next",IF(C7="Low","Later","Set category")))))
J8: =IF(B8="","",(E8="No")+(F8="No")+(G8="No")+(H8="No")+(I8="No")) | K8: =IF(B8="","",IF(J8=0,"Done",IF(C8="High","Fix first",IF(C8="Moderate","Fix next",IF(C8="Low","Later","Set category")))))
J9: =IF(B9="","",(E9="No")+(F9="No")+(G9="No")+(H9="No")+(I9="No")) | K9: =IF(B9="","",IF(J9=0,"Done",IF(C9="High","Fix first",IF(C9="Moderate","Fix next",IF(C9="Low","Later","Set category")))))
J10: =IF(B10="","",(E10="No")+(F10="No")+(G10="No")+(H10="No")+(I10="No")) | K10: =IF(B10="","",IF(J10=0,"Done",IF(C10="High","Fix first",IF(C10="Moderate","Fix next",IF(C10="Low","Later","Set category")))))
J11: =IF(B11="","",(E11="No")+(F11="No")+(G11="No")+(H11="No")+(I11="No")) | K11: =IF(B11="","",IF(J11=0,"Done",IF(C11="High","Fix first",IF(C11="Moderate","Fix next",IF(C11="Low","Later","Set category")))))
J12: =IF(B12="","",(E12="No")+(F12="No")+(G12="No")+(H12="No")+(I12="No")) | K12: =IF(B12="","",IF(J12=0,"Done",IF(C12="High","Fix first",IF(C12="Moderate","Fix next",IF(C12="Low","Later","Set category")))))
J13: =IF(B13="","",(E13="No")+(F13="No")+(G13="No")+(H13="No")+(I13="No")) | K13: =IF(B13="","",IF(J13=0,"Done",IF(C13="High","Fix first",IF(C13="Moderate","Fix next",IF(C13="Low","Later","Set category")))))
J14: =IF(B14="","",(E14="No")+(F14="No")+(G14="No")+(H14="No")+(I14="No")) | K14: =IF(B14="","",IF(J14=0,"Done",IF(C14="High","Fix first",IF(C14="Moderate","Fix next",IF(C14="Low","Later","Set category")))))
J15: =IF(B15="","",(E15="No")+(F15="No")+(G15="No")+(H15="No")+(I15="No")) | K15: =IF(B15="","",IF(J15=0,"Done",IF(C15="High","Fix first",IF(C15="Moderate","Fix next",IF(C15="Low","Later","Set category")))))
J16: =IF(B16="","",(E16="No")+(F16="No")+(G16="No")+(H16="No")+(I16="No")) | K16: =IF(B16="","",IF(J16=0,"Done",IF(C16="High","Fix first",IF(C16="Moderate","Fix next",IF(C16="Low","Later","Set category")))))
J17: =IF(B17="","",(E17="No")+(F17="No")+(G17="No")+(H17="No")+(I17="No")) | K17: =IF(B17="","",IF(J17=0,"Done",IF(C17="High","Fix first",IF(C17="Moderate","Fix next",IF(C17="Low","Later","Set category")))))
J18: =IF(B18="","",(E18="No")+(F18="No")+(G18="No")+(H18="No")+(I18="No")) | K18: =IF(B18="","",IF(J18=0,"Done",IF(C18="High","Fix first",IF(C18="Moderate","Fix next",IF(C18="Low","Later","Set category")))))
J19: =IF(B19="","",(E19="No")+(F19="No")+(G19="No")+(H19="No")+(I19="No")) | K19: =IF(B19="","",IF(J19=0,"Done",IF(C19="High","Fix first",IF(C19="Moderate","Fix next",IF(C19="Low","Later","Set category")))))
... J207: =IF(B207="","",(E207="No")+(F207="No")+(G207="No")+(H207="No")+(I207="No")) | K207: =IF(B207="","",IF(J207=0,"Done",IF(C207="High","Fix first",IF(C207="Moderate","Fix next",IF(C207="Low","Later","Set category")))))

Sheet Resources
B2: Resources | D2: ← Start Here
B3: Where the numbers and ideas in this workbook come from
B6: Threat reports (the stats on Common Attack Vectors)
B8: Verizon 2026 Data Breach Investigations Report (DBIR) | C8: www.verizon.com/business/resources/reports/2026-dbir-data-breach-in…
B9: Verizon 2026 DBIR executive summary | C9: www.verizon.com/business/resources/executivebriefs/2026-dbir-execut…
B10: Verizon DBIR home (all editions) | C10: www.verizon.com/business/resources/reports/dbir/
B12: Protect yourself
B14: CISA Secure Our World – simple steps for everyone | C14: www.cisa.gov/secure-our-world
B15: CISA – Use strong passwords (and a password manager) | C15: www.cisa.gov/secure-our-world/use-strong-passwords
B16: FIDO Alliance – What are passkeys? | C16: fidoalliance.org/passkeys/
B17: Have I Been Pwned – check if your email was in a breach | C17: haveibeenpwned.com/
B19: Standards & frameworks
B21: NIST IR 7298 Rev. 2 – Glossary of Key Information Security Terms | C21: nvlpubs.nist.gov/nistpubs/ir/2013/nist.ir.7298r2.pdf
B22: NIST SP 800-53 Rev. 5 – Security and Privacy Controls | C22: csrc.nist.gov/pubs/sp/800/53/r5/upd1/final
B23: ISO 31000 – Risk management guidelines | C23: www.iso.org/obp/ui/#iso:std:iso:31000:ed-2:v1:en
B25: Hardening guides (STIGs)
B27: DISA STIG document library | C27: www.cyber.mil/stigs/downloads/
B28: DISA SRG & STIG library compilations | C28: www.cyber.mil/stigs/compilations/
B29: STIG Viewer (browse STIGs online) | C29: www.stigviewer.com/stigs
B31: Further reading
B33: Ars Technica – How I learned to stop worrying (mostly) and love my threat model | C33: arstechnica.com/information-technology/2017/07/how-i-learned-to-sto…
B35: Earlier editions (the 2022 version of this workbook)
B37: Verizon 2022 DBIR | C37: www.verizon.com/business/resources/reports/2022/dbir/2022-data-brea…
B38: Kroll Q1 2022 Threat Landscape | C38: www.kroll.com/en/insights/publications/cyber/q1-2022-threat-landsca…
B39: Kaspersky Incident Response Analyst Report 2021 | C39: media.kasperskycontenthub.com/wp-content/uploads/sites/43/2021/09/1…
B40: Kaspersky – The nature of cyber incidents (2022) | C40: media.kasperskycontenthub.com/wp-content/uploads/sites/43/2022/09/0…
